[2018-11-06 21:58:12] load data ...
Traceback (most recent call last):
  File "./src/3_statistics_feature.py", line 82, in <module>
    main()
  File "./src/3_statistics_feature.py", line 52, in main
    data = pd.read_csv(config.ORI_DATA_FILE, sep="\t", encoding="utf-8", low_memory=False)
  File "C:\Users\ZERO\Anaconda3\lib\site-packages\pandas\io\parsers.py", line 655, in parser_f
    return _read(filepath_or_buffer, kwds)
  File "C:\Users\ZERO\Anaconda3\lib\site-packages\pandas\io\parsers.py", line 405, in _read
    parser = TextFileReader(filepath_or_buffer, **kwds)
  File "C:\Users\ZERO\Anaconda3\lib\site-packages\pandas\io\parsers.py", line 764, in __init__
    self._make_engine(self.engine)
  File "C:\Users\ZERO\Anaconda3\lib\site-packages\pandas\io\parsers.py", line 985, in _make_engine
    self._engine = CParserWrapper(self.f, **self.options)
  File "C:\Users\ZERO\Anaconda3\lib\site-packages\pandas\io\parsers.py", line 1605, in __init__
    self._reader = parsers.TextReader(src, **kwds)
  File "pandas/_libs/parsers.pyx", line 394, in pandas._libs.parsers.TextReader.__cinit__ (pandas\_libs\parsers.c:4209)
  File "pandas/_libs/parsers.pyx", line 710, in pandas._libs.parsers.TextReader._setup_parser_source (pandas\_libs\parsers.c:8873)
FileNotFoundError: File b'./data/0_ori_data.txt' does not exist
